#VRML_SIM R2019a utf8
WorldInfo {
}
Viewpoint {
  orientation -0.020115650204698618 0.9908708677938788 0.13330522860806246 3.2594789210887316
  position -0.1013317508503323 1.2595544232600435 -3.0839151451434708
}
TexturedBackground {
}
TexturedBackgroundLight {
}
Floor {
}
Robot {
  translation 0 0.2 0
  children [
    DEF SH_BODY Group {
      children [
        Shape {
          appearance PBRAppearance {
            baseColor 0.9372549019607843 0.1607843137254902 0.1607843137254902
          }
          geometry Box {
            size 0.25 0.08 0.1
          }
        }
        Transform {
          translation 0.1075 -0.0575 0
          children [
            Shape {
              appearance PBRAppearance {
                baseColor 0.9294117647058824 0.8313725490196079 0
              }
              geometry Sphere {
                radius 0.0175
              }
            }
          ]
        }
      ]
    }
    HingeJoint {
      jointParameters HingeJointParameters {
        axis 0 0 1
        anchor -0.05 0 0.065
      }
      device [
        PositionSensor {
          name "position_right"
          resolution 0.005236
        }
        RotationalMotor {
          name "motor_right"
          maxVelocity 52.35987
          maxTorque 0.5931
        }
      ]
      endPoint Solid {
        translation -0.05 0 0.065
        rotation 1 0 0 1.5708
        children [
          DEF SH_WHEEL Shape {
            appearance PBRAppearance {
              baseColor 0 0 0
              roughness 1
              metalness 0
            }
            geometry Cylinder {
              height 0.03
              radius 0.075
            }
          }
        ]
        boundingObject USE SH_WHEEL
        physics Physics {
        }
      }
    }
    HingeJoint {
      jointParameters HingeJointParameters {
        axis 0 0 1
        anchor -0.05 0 -0.065
      }
      device [
        DEF position_left PositionSensor {
          name "position_left"
          resolution 0.005236
        }
        RotationalMotor {
          name "motor_left"
          maxVelocity 52.4
          maxTorque 0.593
        }
      ]
      endPoint Solid {
        translation -0.05 0 -0.065
        rotation 1 0 0 1.5708
        children [
          Shape {
          }
          USE SH_WHEEL
        ]
        name "solid(1)"
        boundingObject USE SH_WHEEL
        physics Physics {
        }
      }
    }
    DistanceSensor {
      translation 0.13 0 0
      children [
        Shape {
          appearance PBRAppearance {
            baseColor 0.5411764705882353 0.8862745098039215 0.20392156862745098
          }
          geometry Box {
            size 0.02 0.02 0.02
          }
        }
      ]
      name "distance_s"
      lookupTable [
        0 0 0
        0.02 0 0
        5 1660 0
      ]
      resolution 1
    }
  ]
  boundingObject USE SH_BODY
  physics Physics {
  }
  controller "crazybot_munoz_samara"
}
